Workbook
Name solver_adj: Sheet1!$R$23:$T$23
Name solver_lhs1: Sheet1!$R$23
Name solver_lhs2: Sheet1!$S$23
Name solver_lhs3: Sheet1!$T$23
Name solver_lhs4: Sheet1!$U$23
Name solver_opt: Sheet1!$R$26

Sheet Sheet1
A1: Start Date | B1: 44562
A2: End Date | B2: 45658
B4: Closing Prices | C4: JPM | D4: MS | E4: GS | G4: Daily Returns | H4: JPM | I4: MS | J4: GS | L4: Risk Summary | M4: JPM | N4: MS | O4: GS | Q4: Equal Weighted Portfolio | R4: JPM | S4: MS | T4: GS | U4: Sum
B5: =IFERROR(__xludf.DUMMYFUNCTION("GOOGLEFINANCE(C4, ""close"", B1, B2)"),"Date") -> Date | C5: =IFERROR(__xludf.DUMMYFUNCTION("""COMPUTED_VALUE"""),"Close") -> Close | D5: Close | E5: Close | G5: Date | H5: Daily Returns | I5: Daily Returns | J5: Daily Returns | L5: Expected Return | M5: =AVERAGE(H7:H758) -> 0.00064765928 | N5: =AVERAGE(I7:I758) -> 0.00045854227 | O5: =AVERAGE(J7:J758) -> 0.00063207183 | Q5: Weights | R5: 0.33333333 | S5: 0.33333333 | T5: 0.33333333 | U5: =SUM(R5:T5) -> 1
B6: =IFERROR(__xludf.DUMMYFUNCTION("""COMPUTED_VALUE"""),44564.6666666666) -> 44564.667 | C6: =IFERROR(__xludf.DUMMYFUNCTION("""COMPUTED_VALUE"""),161.7) -> 161.7 | D6: 100.19 | E6: 395.33 | G6: =B6 -> 44564.667 | L6: Standard Deviation | M6: =_xlfn.STDEV.S(H7:H758) -> 0.015789015 | N6: =_xlfn.STDEV.S(I7:I758) -> 0.017749953 | O6: =_xlfn.STDEV.S(J7:J758) -> 0.016742417 | Q6: Expected Return | R6: =SUMPRODUCT(R5:T5,M5:O5) -> 0.00057942446 | S6: (Daily) | T6: =R6*252 -> 0.14601496 | U6: (Yearly)
B7: =IFERROR(__xludf.DUMMYFUNCTION("""COMPUTED_VALUE"""),44565.6666666666) -> 44565.667 | C7: =IFERROR(__xludf.DUMMYFUNCTION("""COMPUTED_VALUE"""),167.83) -> 167.83 | D7: 104.26 | E7: 407.48 | G7: =B7 -> 44565.667 | H7: =(C7/C6) - 1 -> 0.037909709 | I7: =(D7/D6) - 1 -> 0.040622817 | J7: =(E7/E6) - 1 -> 0.030733817 | L7: Variance | M7: =M6^2 -> 0.000249293 | N7: =N6^2 -> 0.00031506083 | O7: =O6^2 -> 0.00028030853 | Q7: Standard Deviation | R7: {=SQRT(MMULT((R5:T5), MMULT(M12:O14, TRANSPOSE(R5:T5))))} -> 0.015307811 | S7: (Daily) | T7: =R7*SQRT(252) -> 0.24300397 | U7: (Yearly)
B8: =IFERROR(__xludf.DUMMYFUNCTION("""COMPUTED_VALUE"""),44566.6666666666) -> 44566.667 | C8: =IFERROR(__xludf.DUMMYFUNCTION("""COMPUTED_VALUE"""),163.78) -> 163.78 | D8: 101.68 | E8: 398.63 | G8: =B8 -> 44566.667 | H8: =(C8/C7) - 1 -> -0.024131562 | I8: =(D8/D7) - 1 -> -0.024745828 | J8: =(E8/E7) - 1 -> -0.021718857 | L8: Sharpe Ratio | M8: =M5/M6 -> 0.041019612 | N8: =N5/N6 -> 0.025833436 | O8: =O5/O6 -> 0.037752723 | Q8: Sharpe Ratio | R8: =R6/R7 -> 0.037851555 | S8: (Daily) | T8: =T6/T7 -> 0.60087481 | U8: (Yearly)
B9: =IFERROR(__xludf.DUMMYFUNCTION("""COMPUTED_VALUE"""),44567.6666666666) -> 44567.667 | C9: =IFERROR(__xludf.DUMMYFUNCTION("""COMPUTED_VALUE"""),165.52) -> 165.52 | D9: 103.42 | E9: 396.93 | G9: =B9 -> 44567.667 | H9: =(C9/C8) - 1 -> 0.010624008 | I9: =(D9/D8) - 1 -> 0.01711251 | J9: =(E9/E8) - 1 -> -0.0042646063
B10: =IFERROR(__xludf.DUMMYFUNCTION("""COMPUTED_VALUE"""),44568.6666666666) -> 44568.667 | C10: =IFERROR(__xludf.DUMMYFUNCTION("""COMPUTED_VALUE"""),167.16) -> 167.16 | D10: 104.05 | E10: 397.51 | G10: =B10 -> 44568.667 | H10: =(C10/C9) - 1 -> 0.0099081682 | I10: =(D10/D9) - 1 -> 0.0060916651 | J10: =(E10/E9) - 1 -> 0.0014612148 | Q10: Minimum Variance Portfolio | R10: JPM | S10: MS | T10: GS | U10: Sum
B11: =IFERROR(__xludf.DUMMYFUNCTION("""COMPUTED_VALUE"""),44571.6666666666) -> 44571.667 | C11: =IFERROR(__xludf.DUMMYFUNCTION("""COMPUTED_VALUE"""),167.32) -> 167.32 | D11: 104.13 | E11: 399.17 | G11: =B11 -> 44571.667 | H11: =(C11/C10) - 1 -> 0.00095716679 | I11: =(D11/D10) - 1 -> 0.00076886112 | J11: =(E11/E10) - 1 -> 0.0041759956 | L11: Covariance Matrix | M11: JPM | N11: MS | O11: GS | Q11: Weights | R11: 0.56573164 | S11: 0.16151347 | T11: 0.27275589 | U11: =SUM(R11:T11) -> 1.000001
B12: =IFERROR(__xludf.DUMMYFUNCTION("""COMPUTED_VALUE"""),44572.6666666666) -> 44572.667 | C12: =IFERROR(__xludf.DUMMYFUNCTION("""COMPUTED_VALUE"""),167.49) -> 167.49 | D12: 105.92 | E12: 403.05 | G12: =B12 -> 44572.667 | H12: =(C12/C11) - 1 -> 0.0010160172 | I12: =(D12/D11) - 1 -> 0.017190051 | J12: =(E12/E11) - 1 -> 0.0097201694 | L12: JPM | M12: =_xlfn.COVARIANCE.S(H7:H758, H7:H758) -> 0.000249293 | N12: =_xlfn.COVARIANCE.S(H7:H758, I7:I758) -> 0.00019684911 | O12: =_xlfn.COVARIANCE.S(H7:H758, J7:J758) -> 0.00019826231 | Q12: Expected Return | R12: =SUMPRODUCT(R11:T11,M5:O5) -> 0.00061286341 | S12: (Daily) | T12: =R12*252 -> 0.15444158 | U12: (Yearly)
B13: =IFERROR(__xludf.DUMMYFUNCTION("""COMPUTED_VALUE"""),44573.6666666666) -> 44573.667 | C13: =IFERROR(__xludf.DUMMYFUNCTION("""COMPUTED_VALUE"""),168.44) -> 168.44 | D13: 103.05 | E13: 390.31 | G13: =B13 -> 44573.667 | H13: =(C13/C12) - 1 -> 0.0056719804 | I13: =(D13/D12) - 1 -> -0.027095921 | J13: =(E13/E12) - 1 -> -0.031608982 | L13: MS | M13: =_xlfn.COVARIANCE.S(I7:I758, H7:H758) -> 0.00019684911 | N13: =_xlfn.COVARIANCE.S(I7:I758, I7:I758) -> 0.00031506083 | O13: =_xlfn.COVARIANCE.S(I7:I758, J7:J758) -> 0.00023703828 | Q13: Standard Deviation | R13: {=SQRT(MMULT((R11:T11), MMULT(M12:O14, TRANSPOSE(R11:T11))))} -> 0.015063338 | S13: (Daily) | T13: =R13*SQRT(252) -> 0.23912308 | U13: (Yearly)
B14: =IFERROR(__xludf.DUMMYFUNCTION("""COMPUTED_VALUE"""),44574.6666666666) -> 44574.667 | C14: =IFERROR(__xludf.DUMMYFUNCTION("""COMPUTED_VALUE"""),168.23) -> 168.23 | D14: 102.55 | E14: 390.8 | G14: =B14 -> 44574.667 | H14: =(C14/C13) - 1 -> -0.0012467347 | I14: =(D14/D13) - 1 -> -0.0048520136 | J14: =(E14/E13) - 1 -> 0.0012554124 | L14: GS | M14: =_xlfn.COVARIANCE.S(J7:J758, H7:H758) -> 0.00019826231 | N14: =_xlfn.COVARIANCE.S(J7:J758, I7:I758) -> 0.00023703828 | O14: =_xlfn.COVARIANCE.S(J7:J758, J7:J758) -> 0.00028030853 | Q14: Sharpe Ratio | R14: =R12/R13 -> 0.040685763 | S14: (Daily) | T14: =T12/T13 -> 0.64586647 | U14: (Yearly)
B15: =IFERROR(__xludf.DUMMYFUNCTION("""COMPUTED_VALUE"""),44575.6666666666) -> 44575.667 | C15: =IFERROR(__xludf.DUMMYFUNCTION("""COMPUTED_VALUE"""),157.89) -> 157.89 | D15: 98.88 | E15: 380.94 | G15: =B15 -> 44575.667 | H15: =(C15/C14) - 1 -> -0.061463473 | I15: =(D15/D14) - 1 -> -0.035787421 | J15: =(E15/E14) - 1 -> -0.025230297
B16: =IFERROR(__xludf.DUMMYFUNCTION("""COMPUTED_VALUE"""),44579.6666666666) -> 44579.667 | C16: =IFERROR(__xludf.DUMMYFUNCTION("""COMPUTED_VALUE"""),151.27) -> 151.27 | D16: 94.01 | E16: 354.4 | G16: =B16 -> 44579.667 | H16: =(C16/C15) - 1 -> -0.041927925 | I16: =(D16/D15) - 1 -> -0.049251618 | J16: =(E16/E15) - 1 -> -0.069669764 | L16: Correlation Matrix | M16: JPM | N16: MS | O16: GS | Q16: Maximum Returns Portfolio | R16: JPM | S16: MS | T16: GS | U16: Sum
B17: =IFERROR(__xludf.DUMMYFUNCTION("""COMPUTED_VALUE"""),44580.6666666666) -> 44580.667 | C17: =IFERROR(__xludf.DUMMYFUNCTION("""COMPUTED_VALUE"""),148.93) -> 148.93 | D17: 95.73 | E17: 347.32 | G17: =B17 -> 44580.667 | H17: =(C17/C16) - 1 -> -0.015469029 | I17: =(D17/D16) - 1 -> 0.018295926 | J17: =(E17/E16) - 1 -> -0.019977427 | L17: JPM | M17: =CORREL(H7:H758, H7:H758) -> 1 | N17: =CORREL(H7:H758, I7:I758) -> 0.70239466 | O17: =CORREL(H7:H758, J7:J758) -> 0.75000984 | Q17: Weights | R17: 1.000001 | S17: 0 | T17: 0 | U17: =SUM(R17:T17) -> 1.000001
B18: =IFERROR(__xludf.DUMMYFUNCTION("""COMPUTED_VALUE"""),44581.6666666666) -> 44581.667 | C18: =IFERROR(__xludf.DUMMYFUNCTION("""COMPUTED_VALUE"""),147.66) -> 147.66 | D18: 99.83 | E18: 348.1 | G18: =B18 -> 44581.667 | H18: =(C18/C17) - 1 -> -0.0085274961 | I18: =(D18/D17) - 1 -> 0.042828789 | J18: =(E18/E17) - 1 -> 0.0022457676 | L18: MS | M18: =CORREL(I7:I758, H7:H758) -> 0.70239466 | N18: =CORREL(I7:I758, I7:I758) -> 1 | O18: =CORREL(I7:I758, J7:J758) -> 0.79763303 | Q18: Expected Return | R18: =SUMPRODUCT(R17:T17,M5:O5) -> 0.00064765992 | S18: (Daily) | T18: =R18*252 -> 0.1632103 | U18: (Yearly)
B19: =IFERROR(__xludf.DUMMYFUNCTION("""COMPUTED_VALUE"""),44582.6666666666) -> 44582.667 | C19: =IFERROR(__xludf.DUMMYFUNCTION("""COMPUTED_VALUE"""),145.08) -> 145.08 | D19: 98.86 | E19: 343.91 | G19: =B19 -> 44582.667 | H19: =(C19/C18) - 1 -> -0.017472572 | I19: =(D19/D18) - 1 -> -0.0097165181 | J19: =(E19/E18) - 1 -> -0.012036771 | L19: GS | M19: =CORREL(J7:J758, H7:H758) -> 0.75000984 | N19: =CORREL(J7:J758, I7:I758) -> 0.79763303 | O19: =CORREL(J7:J758, J7:J758) -> 1 | Q19: Standard Deviation | R19: {=SQRT(MMULT((R17:T17), MMULT(M12:O14, TRANSPOSE(R17:T17))))} -> 0.015789031 | S19: (Daily) | T19: =R19*SQRT(252) -> 0.2506431 | U19: (Yearly)
B20: =IFERROR(__xludf.DUMMYFUNCTION("""COMPUTED_VALUE"""),44585.6666666666) -> 44585.667 | C20: =IFERROR(__xludf.DUMMYFUNCTION("""COMPUTED_VALUE"""),144.95) -> 144.95 | D20: 98.08 | E20: 343.39 | G20: =B20 -> 44585.667 | H20: =(C20/C19) - 1 -> -0.00089605735 | I20: =(D20/D19) - 1 -> -0.0078899454 | J20: =(E20/E19) - 1 -> -0.0015120235 | Q20: Sharpe Ratio | R20: =R18/R19 -> 0.041019612 | S20: (Daily) | T20: =T18/T19 -> 0.65116615 | U20: (Yearly)
B21: =IFERROR(__xludf.DUMMYFUNCTION("""COMPUTED_VALUE"""),44586.6666666666) -> 44586.667 | C21: =IFERROR(__xludf.DUMMYFUNCTION("""COMPUTED_VALUE"""),146.53) -> 146.53 | D21: 99.04 | E21: 341.55 | G21: =B21 -> 44586.667 | H21: =(C21/C20) - 1 -> 0.01090031 | I21: =(D21/D20) - 1 -> 0.0097879282 | J21: =(E21/E20) - 1 -> -0.0053583389
B22: =IFERROR(__xludf.DUMMYFUNCTION("""COMPUTED_VALUE"""),44587.6666666666) -> 44587.667 | C22: =IFERROR(__xludf.DUMMYFUNCTION("""COMPUTED_VALUE"""),147.92) -> 147.92 | D22: 100.17 | E22: 342.68 | G22: =B22 -> 44587.667 | H22: =(C22/C21) - 1 -> 0.0094861121 | I22: =(D22/D21) - 1 -> 0.011409532 | J22: =(E22/E21) - 1 -> 0.0033084468 | Q22: Maximum Sharpe Portfolio | R22: JPM | S22: MS | T22: GS | U22: Sum
B23: =IFERROR(__xludf.DUMMYFUNCTION("""COMPUTED_VALUE"""),44588.6666666666) -> 44588.667 | C23: =IFERROR(__xludf.DUMMYFUNCTION("""COMPUTED_VALUE"""),145.31) -> 145.31 | D23: 101.15 | E23: 341.03 | G23: =B23 -> 44588.667 | H23: =(C23/C22) - 1 -> -0.017644673 | I23: =(D23/D22) - 1 -> 0.0097833683 | J23: =(E23/E22) - 1 -> -0.0048149877 | Q23: Weights | R23: 0.65846568 | S23: 0 | T23: 0.34153432 | U23: =SUM(R23:T23) -> 1
B24: =IFERROR(__xludf.DUMMYFUNCTION("""COMPUTED_VALUE"""),44589.6666666666) -> 44589.667 | C24: =IFERROR(__xludf.DUMMYFUNCTION("""COMPUTED_VALUE"""),146.61) -> 146.61 | D24: 101.8 | E24: 347.01 | G24: =B24 -> 44589.667 | H24: =(C24/C23) - 1 -> 0.0089463905 | I24: =(D24/D23) - 1 -> 0.0064260999 | J24: =(E24/E23) - 1 -> 0.017535114 | Q24: Expected Return | R24: =SUMPRODUCT(R23:T23,M5:O5) -> 0.00064233563 | S24: (Daily) | T24: =R24*252 -> 0.16186858 | U24: (Yearly)
B25: =IFERROR(__xludf.DUMMYFUNCTION("""COMPUTED_VALUE"""),44592.6666666666) -> 44592.667 | C25: =IFERROR(__xludf.DUMMYFUNCTION("""COMPUTED_VALUE"""),148.6) -> 148.6 | D25: 102.54 | E25: 354.68 | G25: =B25 -> 44592.667 | H25: =(C25/C24) - 1 -> 0.013573426 | I25: =(D25/D24) - 1 -> 0.0072691552 | J25: =(E25/E24) - 1 -> 0.022103109 | Q25: Standard Deviation | R25: {=SQRT(MMULT((R23:T23), MMULT(M12:O14, TRANSPOSE(R23:T23))))} -> 0.015164379 | S25: (Daily) | T25: =R25*SQRT(252) -> 0.24072705 | U25: (Yearly)
B26: =IFERROR(__xludf.DUMMYFUNCTION("""COMPUTED_VALUE"""),44593.6666666666) -> 44593.667 | C26: =IFERROR(__xludf.DUMMYFUNCTION("""COMPUTED_VALUE"""),151.15) -> 151.15 | D26: 103.95 | E26: 364.06 | G26: =B26 -> 44593.667 | H26: =(C26/C25) - 1 -> 0.017160162 | I26: =(D26/D25) - 1 -> 0.013750731 | J26: =(E26/E25) - 1 -> 0.026446374 | Q26: Sharpe Ratio | R26: =R24/R25 -> 0.042358189 | S26: (Daily) | T26: =T24/T25 -> 0.67241541 | U26: (Yearly)
B27: =IFERROR(__xludf.DUMMYFUNCTION("""COMPUTED_VALUE"""),44594.6666666666) -> 44594.667 | C27: =IFERROR(__xludf.DUMMYFUNCTION("""COMPUTED_VALUE"""),149.94) -> 149.94 | D27: 103.92 | E27: 363.06 | G27: =B27 -> 44594.667 | H27: =(C27/C26) - 1 -> -0.0080052928 | I27: =(D27/D26) - 1 -> -0.00028860029 | J27: =(E27/E26) - 1 -> -0.0027468
B28: =IFERROR(__xludf.DUMMYFUNCTION("""COMPUTED_VALUE"""),44595.6666666666) -> 44595.667 | C28: =IFERROR(__xludf.DUMMYFUNCTION("""COMPUTED_VALUE"""),148.7) -> 148.7 | D28: 102.29 | E28: 358.88 | G28: =B28 -> 44595.667 | H28: =(C28/C27) - 1 -> -0.0082699747 | I28: =(D28/D27) - 1 -> -0.015685142 | J28: =(E28/E27) - 1 -> -0.011513248
B29: =IFERROR(__xludf.DUMMYFUNCTION("""COMPUTED_VALUE"""),44596.6666666666) -> 44596.667 | C29: =IFERROR(__xludf.DUMMYFUNCTION("""COMPUTED_VALUE"""),152.56) -> 152.56 | D29: 104.11 | E29: 367.6 | G29: =B29 -> 44596.667 | H29: =(C29/C28) - 1 -> 0.025958305 | I29: =(D29/D28) - 1 -> 0.017792551 | J29: =(E29/E28) - 1 -> 0.024297815
B30: =IFERROR(__xludf.DUMMYFUNCTION("""COMPUTED_VALUE"""),44599.6666666666) -> 44599.667 | C30: =IFERROR(__xludf.DUMMYFUNCTION("""COMPUTED_VALUE"""),153.07) -> 153.07 | D30: 105.18 | E30: 368.15 | G30: =B30 -> 44599.667 | H30: =(C30/C29) - 1 -> 0.003342947 | I30: =(D30/D29) - 1 -> 0.010277591 | J30: =(E30/E29) - 1 -> 0.0014961915
B31: =IFERROR(__xludf.DUMMYFUNCTION("""COMPUTED_VALUE"""),44600.6666666666) -> 44600.667 | C31: =IFERROR(__xludf.DUMMYFUNCTION("""COMPUTED_VALUE"""),155.95) -> 155.95 | D31: 106.35 | E31: 370.1 | G31: =B31 -> 44600.667 | H31: =(C31/C30) - 1 -> 0.018814921 | I31: =(D31/D30) - 1 -> 0.011123788 | J31: =(E31/E30) - 1 -> 0.005296754
B32: =IFERROR(__xludf.DUMMYFUNCTION("""COMPUTED_VALUE"""),44601.6666666666) -> 44601.667 | C32: =IFERROR(__xludf.DUMMYFUNCTION("""COMPUTED_VALUE"""),156.6) -> 156.6 | D32: 108.73 | E32: 374.53 | G32: =B32 -> 44601.667 | H32: =(C32/C31) - 1 -> 0.0041680026 | I32: =(D32/D31) - 1 -> 0.022378937 | J32: =(E32/E31) - 1 -> 0.011969738
B33: =IFERROR(__xludf.DUMMYFUNCTION("""COMPUTED_VALUE"""),44602.6666666666) -> 44602.667 | C33: =IFERROR(__xludf.DUMMYFUNCTION("""COMPUTED_VALUE"""),155.95) -> 155.95 | D33: 107.57 | E33: 370.57 | G33: =B33 -> 44602.667 | H33: =(C33/C32) - 1 -> -0.0041507024 | I33: =(D33/D32) - 1 -> -0.010668629 | J33: =(E33/E32) - 1 -> -0.010573252
B34: =IFERROR(__xludf.DUMMYFUNCTION("""COMPUTED_VALUE"""),44603.6666666666) -> 44603.667 | C34: =IFERROR(__xludf.DUMMYFUNCTION("""COMPUTED_VALUE"""),153.92) -> 153.92 | D34: 104.57 | E34: 363.06 | G34: =B34 -> 44603.667 | H34: =(C34/C33) - 1 -> -0.013016993 | I34: =(D34/D33) - 1 -> -0.027888817 | J34: =(E34/E33) - 1 -> -0.020266077
B35: =IFERROR(__xludf.DUMMYFUNCTION("""COMPUTED_VALUE"""),44606.6666666666) -> 44606.667 | C35: =IFERROR(__xludf.DUMMYFUNCTION("""COMPUTED_VALUE"""),152.49) -> 152.49 | D35: 102.57 | E35: 360.24 | G35: =B35 -> 44606.667 | H35: =(C35/C34) - 1 -> -0.0092905405 | I35: =(D35/D34) - 1 -> -0.019125944 | J35: =(E35/E34) - 1 -> -0.0077673112
B36: =IFERROR(__xludf.DUMMYFUNCTION("""COMPUTED_VALUE"""),44607.6666666666) -> 44607.667 | C36: =IFERROR(__xludf.DUMMYFUNCTION("""COMPUTED_VALUE"""),154.72) -> 154.72 | D36: 103.43 | E36: 363.94 | G36: =B36 -> 44607.667 | H36: =(C36/C35) - 1 -> 0.01462391 | I36: =(D36/D35) - 1 -> 0.0083845179 | J36: =(E36/E35) - 1 -> 0.01027093
B37: =IFERROR(__xludf.DUMMYFUNCTION("""COMPUTED_VALUE"""),44608.6666666666) -> 44608.667 | C37: =IFERROR(__xludf.DUMMYFUNCTION("""COMPUTED_VALUE"""),155) -> 155 | D37: 101.15 | E37: 360.05 | G37: =B37 -> 44608.667 | H37: =(C37/C36) - 1 -> 0.0018097208 | I37: =(D37/D36) - 1 -> -0.022043894 | J37: =(E37/E36) - 1 -> -0.010688575
B38: =IFERROR(__xludf.DUMMYFUNCTION("""COMPUTED_VALUE"""),44609.6666666666) -> 44609.667 | C38: =IFERROR(__xludf.DUMMYFUNCTION("""COMPUTED_VALUE"""),151.43) -> 151.43 | D38: 96.15 | E38: 349.06 | G38: =B38 -> 44609.667 | H38: =(C38/C37) - 1 -> -0.023032258 | I38: =(D38/D37) - 1 -> -0.049431537 | J38: =(E38/E37) - 1 -> -0.030523538
B39: =IFERROR(__xludf.DUMMYFUNCTION("""COMPUTED_VALUE"""),44610.6666666666) -> 44610.667 | C39: =IFERROR(__xludf.DUMMYFUNCTION("""COMPUTED_VALUE"""),152.14) -> 152.14 | D39: 95.42 | E39: 346.04 | G39: =B39 -> 44610.667 | H39: =(C39/C38) - 1 -> 0.004688635 | I39: =(D39/D38) - 1 -> -0.0075923037 | J39: =(E39/E38) - 1 -> -0.0086518077
B40: =IFERROR(__xludf.DUMMYFUNCTION("""COMPUTED_VALUE"""),44614.6666666666) -> 44614.667 | C40: =IFERROR(__xludf.DUMMYFUNCTION("""COMPUTED_VALUE"""),151.87) -> 151.87 | D40: 94.75 | E40: 344.27 | G40: =B40 -> 44614.667 | H40: =(C40/C39) - 1 -> -0.0017746812 | I40: =(D40/D39) - 1 -> -0.0070215888 | J40: =(E40/E39) - 1 -> -0.0051150156
B41: =IFERROR(__xludf.DUMMYFUNCTION("""COMPUTED_VALUE"""),44615.6666666666) -> 44615.667 | C41: =IFERROR(__xludf.DUMMYFUNCTION("""COMPUTED_VALUE"""),148.69) -> 148.69 | D41: 93.55 | E41: 341.19 | G41: =B41 -> 44615.667 | H41: =(C41/C40) - 1 -> -0.020938961 | I41: =(D41/D40) - 1 -> -0.012664908 | J41: =(E41/E40) - 1 -> -0.0089464664
...

Sheet __OpenSolverCache__

Sheet __OpenSolver__
A1: =ModelSheet=Sheet1!A:Z -> #NAME?
A2: =OpenSolver_AdjNum=1 -> #NAME?
A3: =OpenSolver_ChosenSolver=Google -> #NAME?
A4: =OpenSolver_FastBuild=0 -> #NAME?
A5: =OpenSolver_LinearityCheck=1 -> #NAME?
A6: =solver_adj=Sheet1!R11:T11 -> #NAME?
A7: =solver_lhs1=Sheet1!U11 -> #NAME?
A8: =solver_neg=1 -> #NAME?
A9: =solver_num=1 -> #NAME?
A10: =solver_opt=Sheet1!R13 -> #NAME?
A11: =solver_rel1=2 -> #NAME?
A12: =solver_rhs1=Sheet1!U5 -> #NAME?
A13: =solver_sho=1 -> #NAME?
A14: =solver_typ=2 -> #NAME?
A15: =solver_val=0 -> #NAME?
